Workbook

Sheet Perfiles 
C2: PERFILES RAYENTUÉ
C4: FECHA ACTUALIZACIÓN | D4: 45199
C7: RESPONSABLE | D7: CHRISTIAN NUÑEZ BERRIOS- (13-05-2025)
B8: AÑO | C8: CONCURSO O LINEA | D8: CRI | E8: TÍTULO | F8: Programas Nacionales | G8: Investigador/a Encargado/a | H8: Ejecutor Principal | I8: ID- Perfil | J8: Estado Perfil | K8: Postulado | L8: Adjudicado | M8: Comentarios
B9: 44428 | C9: FIA Asignacion Directa | D9: 16-Rayentue | E9: Desarrollo de soluciones técnicas de manejo sustentable de suelos, agua y cultivos, para mejorar la situación post incendios forestales en predios de agricultores del área de secano de la región de O`Higgins y mitigar la problemática del cambio climático | F9: Agrosistemas Sustentables | G9: CARRASCO JIMENEZ JORGE | H9: INIA | I9: Sin Información | J9: Adjudicado | K9: SI | L9: Si
B10: 44414 | C10: FONTAGRO | D10: 16-Rayentue | E10: Agtechmetro | F10: Agrosistemas Sustentables | G10: FELMER ECHEVERRIA, SOFIA | H10: U. AUSTRAL | I10: Sin Información | J10: N/A | K10: SI | L10: RECHAZADO
B11: 43924 | C11: Súmate a Innovar - INNOVA-CORFO | D11: 16-Rayentue | E11: Efecto de la humidificación durante la cosecha de paltas para mejorar la condición de la fruta post-frío | F11: Producción Vegetal | G11: OTAROLA ALIAGA, JAIME IGNACIO | H11: INIA | I11: Sin Información | J11: Perfil Seleccionado | K11: NO | L11: NO APLICA | M11: No se realiza postulación porque la empresa interesada no puede realizar el aporte por la situación económica causada por COVID-19
B12: 43776 | C12: Anillos de Investigacion en Ciencia Y tecnolog a para la Regi n de O Higgins 2019 | D12: 16-RAYENTUE, 20-QUILAMAPU, 13-LA CRUZ | E12: Deep insight in the cherry plant defense responses tobacterial canker disease in a scenario of water restriction | F12: Producción Vegetal | G12: SAGREDO DIAZ, BORIS | H12: UOH | I12: Sin Información | J12: Perfil Seleccionado | K12: SI | L12: NO APLICA
B13: 43776 | C13: X Concurso de Equipamiento Cientifico y Tecnologico FONDEQUIP Regi n de O Higgins a o 2019 | D13: 16-RAYENTUE, 20-QUILAMAPU, 13-LA CRUZ | E13: Desarrollo de una plataforma de análisis de fragmentos y secuencias de ADN para fortalecer el desarrollo científico y tecnológico de la Región de O Higgins | F13: Producción Vegetal | G13: SAGREDO DIAZ, BORIS | H13: INIA | I13: Sin Información | J13: Perfil no Seleccionado | K13: SI | L13: NO APLICA
A14: 1 | B14: 43775 | C14: X Concurso de Equipamiento Cient fico y Tecnol gico FONDEQUIP Regi n de O Higgins a o 2019 | D14: 16-Rayentue | E14: Fortalecimiento y ampliación de un laboratorio de física de suelos y riego para su consolidación en la investigación y servicios en la región de O Higgins | F14: Agrosistemas Sustentables | G14: CARRASCO JIMENEZ JORGE | H14: INIA | I14: Sin Información | J14: En revisión por SubDirector Regional de I+D | K14: NO | L14: NO APLICA
B15: 43731 | C15: Convocatoria Nacional Proyectos de Innovación 2019 FIA | D15: 10-La Platina, 16-Rayentue, 20-Quilamapu, 30-Carillanca | E15: Conociendo la dinámica poblacional de Pseudomonas syringae para un control mas efectivo y sustentable del cáncer bacterial en Cerezos en Chile | F15: Producción Vegetal | G15: SAGREDO DIAZ, BORIS | H15: INIA | I15: Sin Información | J15: Perfil no Seleccionado | K15: NO | L15: NO APLICA
A16: 1 | B16: 43731 | C16: Convocatoria Nacional Proyectos de Innovación 2019 FIA | D16: 16-Rayentue, 20-Quilamapu | E16: Bioinmunizador microbiano endófito para el manejo agroecológico de la cebolla como estrategia para disminuir el uso de agroquímicos en el cultivo. | F16: Agrosistemas Sustentables | G16: VEGA CANDIA, BARBARA CHANTAL | H16: INIA | I16: Sin Información | J16: Perfil Seleccionado | K16: SI | L16: RECHAZADO | M16: NO APARECE EN LA LISTA DE PROYECTOS QUE PASARON LA 1° ETAPA
A17: 2 | B17: 43724 | C17: Convocatoria Nacional Proyectos de Innovación 2019 FIA | D17: 16-Rayentue | E17: Manejos sustentables para enfrentar un escenario de sequía en huertos frutales | F17: Producción Vegetal | G17: OTAROLA ALIAGA, JAIME IGNACIO | H17: INIA | I17: Sin Información | J17: Perfil no Seleccionado | K17: NO | L17: NO APLICA
A18: 3 | B18: 43711 | C18: FONDECYT DE POSTDOCTORADO 2020 | D18: 16-Rayentue, 15-Hidango, 20-Quilamapu, 14-Los Tilos | E18: DETERMINACIÓN DE LAS BASES FISIOLÓGICAS DE LA ADAPTACIÓN DE GENOTIPOS DE TRIGO CANDEAL DE INIA A CONDICIONES DE SEQUÍA EN EL SECANO MEDITERRÁNEO DE CHILE | F18: Producción Vegetal | G18: ALFARO JARA, CHRISTIAN EUGENIO | H18: INIA | I18: Sin Información | J18: Perfil Seleccionado | K18: SI | L18: NO APLICA
A19: 4 | B19: 43711 | C19: VIII Concurso de Investigación Tecnológica 2019-IDeA | D19: 16-Rayentue | E19: Validación de la tecnología de nanoburbujas en distintos niveles de la cadena de producción de fruta fresca | F19: Producción Vegetal | G19: OTAROLA ALIAGA, JAIME IGNACIO | H19: INIA | I19: Sin Información | J19: Perfil Seleccionado | K19: SI | L19: NO APLICA
A20: 5 | B20: 43711 | C20: VIII Concurso de Investigación Tecnológica 2019-IDeA | D20: 10-La Platina, 16-Rayentue, 20-Quilamapu, 30-Carillanca | E20: Nuevas herramientas de monitoreo de poblaciones de Pseudomonas syringae agente causal del cáncer bacterial en cerezos para apoyar sistemas integrados de control y reducir contaminación con Cu+2. | F20: Producción Vegetal | G20: SAGREDO DIAZ, BORIS | H20: INIA | I20: Sin Información | J20: Perfil Seleccionado | K20: SI | L20: NO APLICA
A21: 6 | B21: 43685 | C21: Bienes Públicos 2019- Temática "Adaptación al Cambio Climático" | D21: 16-Rayentue | E21: Adaptación al manejo agronómico del cultivo de cerezo desarrollado bajo cubiertas plásticas | F21: Producción Vegetal | G21: OTAROLA ALIAGA, JAIME IGNACIO | H21: INIA | I21: Sin Información | J21: Perfil Seleccionado | K21: SI | L21: NO APLICA | M21: No es pertinente
A22: 7 | B22: 43681 | C22: Bienes Públicos 2019- Temática "Adaptación al Cambio Climático" | D22: 16-Rayentue | E22: Manejo de frutales ante un escenario de sequía en la región de O’Higgins | F22: Producción Vegetal | G22: OTAROLA ALIAGA, JAIME IGNACIO | H22: INIA | I22: Sin Información | J22: En revisión por SubDirector Regional de I+D | K22: NO | L22: NO APLICA
A23: 8 | B23: 43677 | C23: Bienes Públicos 2019- Temática "Adaptación al Cambio Climático" | D23: 16-Rayentue | E23: Generación de una línea base para el establecimiento frutal en el valle de Nilahue con disponibilidad de agua de riego a través del embalse Convento Viejo. | F23: Producción Vegetal | G23: OTAROLA ALIAGA, JAIME IGNACIO | H23: INIA | I23: Sin Información | J23: En revisión por SubDirector Regional de I+D | K23: NO | L23: NO APLICA
A24: 9 | B24: 43656 | C24: Concurso Postdoctorado 2019 | D24: Rayentué | E24: INTERACCIÓN G X E DE CARACTERES DE ADAPTACIÓN A CONDICIONES DE ESTRÉS HÍDRICO EN Y SU EFECTO SOBRE LA DETERMINACIÓN DEL RENDIMIENTO EN TRIGO CANDEAL | F24: Producción Vegetal | G24: ALFARO JARA, CHRISTIAN EUGENIO | H24: INIA | I24: Sin Información | J24: Perfil Seleccionado | K24: SI | L24: RECHAZADO
A25: 10 | B25: 43656 | C25: Concurso Regular Fondecyt 2019 | D25: Rayentué | E25: MECANISMOS HIDRAULICOS Y DE METABOLISMO DEL CARBONO EN LA ADAPTACION DEL CULTIVO DE TRIGO A CONDICIONES DE CAMBIO CLIMÁTICO EN AMBIENTES DE SEQUIA SEVERA DE TIPO MEDITERRANEO | F25: Producción Vegetal | G25: ALFARO JARA, CHRISTIAN EUGENIO | H25: INIA | I25: Sin Información | J25: Perfil Seleccionado | K25: NO | L25: NO APLICA
A26: 11 | B26: 43642 | C26: XXIII Concurso Nacional de Proyectos Explora para elaboración de productos de divulgación de las ciencias y la tecnología 2019 2020 | D26: 16-RAYENTUE, 15-HIDANGO | E26: NATIVOAPP 2 0 Plataforma móvil y web para mapear e identificarflora nativa en Chile | F26: Producción Vegetal | G26: SAGREDO DIAZ, BORIS | H26: INIA | I26: Sin Información | J26: APROBADO | K26: SI | L26: RECHAZADO | M26: no adjudicar la propuesta, debido a que la solución no está debidamente identiﬁcada
A27: 12 | B27: 43628 | C27: IX Concurso de Vinculación Ciencia Empresa | D27: 16-RAYENTUE, 01-DIRECCIÓN NACIONAL | E27: Vinculación Ciencia Empresa Una Plataforma Científico Técnica para enfrentar los desafíos ante el aumento de cobertura de riego del ECV Embalse Convento Viejo en la comuna de Marchigue | F27: Producción Vegetal | G27: SAGREDO DIAZ, BORIS | H27: INIA | I27: Sin Información | J27: APROBADO | K27: NO | L27: NO APLICA | M27: No alcanzo a presentarlo a la FF
A28: 13 | B28: 43620 | C28: Concurso Regular Fondecyt 2020 | D28: 14-LOS TILOS, 16-RAYENTUE, 10-LA PLATINA, 05-INTIHUASI | E28: Disentangling the epigenetic influence on fruit development and ripening in three stone fruits Prunus species | F28: Producción Vegetal | G28: DONOSO CONTRERAS, JOSE MANUEL | H28: U. de Chile | I28: Sin Información | J28: APROBADO | K28: SI | L28: APROBADO
A29: 14 | B29: 43616 | C29: PCI ECOS CONICYT Concurso de proyectos de intercambio Chile Francia 2019 | D29: 14-LOS TILOS, 10-LA PLATINA, 16-RAYENTUE | E29: Collaborative counter season research efforts between France and Chile analysis of traits affected by climate change in sweet cherry in order to create new varieties adapted to future environmental conditions | F29: Producción Vegetal | G29: DONOSO CONTRERAS, JOSE MANUEL | H29: INIA | I29: Sin Información | J29: APROBADO | K29: SI | L29: RECHAZADO
A30: 1 | B30: 43493 | C30: CONCURSO IDEA I+D 2019 | D30: 16-RAYENTUE, 20-QUILAMAPU | E30: Plataforma de Información Epidemiologica para facilitar el control del Cáncer Bacterial en Cerezos | F30: Producción Vegetal | G30: SAGREDO DIAZ, BORIS | H30: INIA | I30: Sin Información | J30: APROBADO | K30: SI | L30: RECHAZADO
A31: 2 | B31: 43291 | C31: Septimo Concurso de Investigaci n Tecnol gica 2018 IDeA | D31: Rayentué | E31: Plataforma de Información Epidemiologica para facilitar el control del Cáncer Bacterial en Cerezos | F31: Producción Vegetal | G31: SAGREDO DIAZ, BORIS | H31: INIA | I31: Sin Información | J31: Perfil Seleccionado | K31: NO | L31: NO APLICA | M31: NO SE ALCANZO A POSTULAR
A32: 3 | B32: 43291 | C32: Otros Concursos de alcance nacional o regional 2018 | D32: Rayentué | E32: Identificación de marcadores moleculares asociados a la determinación del sexo en maqui A chilensis y su ubicación a nivel cromosómico | F32: Producción Vegetal | G32: SAGREDO DIAZ, BORIS | H32: INIA | I32: Sin Información | J32: En revisión por SubDirector Regional de I+D | K32: SI | L32: RECHAZADO
A33: 4 | B33: 43291 | C33: Otros Concursos de alcance nacional o regional 2018 | D33: Rayentué | E33: Plataforma de Información Epidemiologica para facilitar el control del Cáncer Bacterial en Cerezos | F33: Producción Vegetal | G33: SAGREDO DIAZ, BORIS | H33: INIA | I33: Sin Información | J33: En revisión por SubDirector Regional de I+D | K33: NO | L33: NO APLICA | M33: NO SE ALCANZO A POSTULAR
A34: 5 | B34: 43291 | C34: FIA-Convocatoria Nacional Giras Nacionales para la Innovaci n de la Peque a Agricultura 2018 | D34: Rayentué | E34: Adquisición de conocimientos en el control biológico de plagas y enfermedades en las principales hortalizas de la región de O higgins | F34: Agrosistemas Sustentables | G34: VEGA CANDIA, BARBARA CHANTAL | H34: INIA | I34: Sin Información | J34: Perfil Seleccionado | K34: SI | L34: RECHAZADO
A35: 6 | B35: 43291 | C35: Otros Concursos de alcance nacional o regional 2018 | D35: Rayentué | E35: Captura de conocimientos y experiencias en el manejo sustentable del cultivo del tomate | F35: Agrosistemas Sustentables | G35: VEGA CANDIA, BARBARA CHANTAL | H35: INIA | I35: Sin Información | J35: En corrección por Comisión de Evaluación Nacional | K35: SI | L35: RECHAZADO
A36: 7 | B36: 46126 | C36: Fondecyt de Iniciación en Investigación 2027 | D36: 16-Rayentué | E36: Predictive physiological traits for robust quinoa selection across dynamic drought-prone Mediterranean environments | F36: Programa Nacional de Producción Vegetal | G36: ESTRADA BRAVO, FELIX RODOLFO | H36: INIA | I36: 1659 | J36: Seleccionado con condiciones | M36: En concurso
A37: 8 | B37: 46056 | C37: XVII Concurso Fondo de Investigación del Bosque Nativo-CONAF 2026 | D37: 16-Rayentué | E37: Restauración de bosques fragmentados del secano costero de la Región de O’Higgins mediante el uso de especies nodrizas leñosas y cactáceas nativas | F37: Programa Nacional de Agrosistemas Sustentables | G37: CACERES CELEDON, EMILIO JOSE | H37: INIA | I37: 1617 | J37: Postulado | K37: Si | M37: En concurso
A38: 9 | B38: 46051 | C38: Concurso de Investigación Tecnológica IDeA 2026 | D38: 16-Rayentué | E38: Hacia un control mas sustentable del cáncer bacterial en cerezos: reducción del uso de cobre y pérdidas productivas mediante herramientas biotecnológicas y monitoreo molecular predictivo | F38: Programa Nacional de Producción Vegetal | G38: SAGREDO DIAZ, BORIS | H38: INIA | I38: 1615 | J38: Postulado | K38: Si | M38: En concurso
A39: 10 | B39: 45944 | C39: Viraliza Eventos 2025 | D39: Rayentué | E39: Viraliza Agro Tech O’Higgins (Viraliza Eventos 2025) | F39: Programa Nacional de Agrosistemas Sustentables | G39: AGUIRRE AGUILERA, CRISTIAN | H39: UOH - Universidad de O'Higgins | I39: 1553 | J39: Postulado | K39: Si | L39: Si | M39: En concurso
A40: 11 | B40: 45901 | C40: Consultorías Regionales para la Innovación 2025 | D40: Rayentué | E40: Gestión eficiente del agua de riego de Convento Viejo 2: diagnóstico de suelos, riego y cultivos en las comunas de Lolol, Pumanque y Marchigue | F40: Programa Nacional de Agrosistemas Sustentables | G40: CACERES CELEDON, EMILIO JOSE | H40: INIA | I40: 1523 | J40: Postulado | K40: Si | L40: Si | M40: En concurso
A41: 12 | B41: 45901 | C41: Giras nacionales de innovación para Mujeres Agroinnovadoras 2025 | D41: Rayentué | E41: Raíces femeninas: Gira agroecológica de mujeres transformadoras | F41: Programa Nacional de Agrosistemas Sustentables | G41: VEGA CANDIA, BARBARA CHANTAL | H41: INIA | I41: 1522 | J41: Postulado | K41: Si | L41: No | M41: En concurso
B42: 45886 | C42: Startup Ciencia 2026 | D42: Rayentué | E42: Optiriego Plus: Aceleramiento del desarrollo tecnológico y comercial del sensor Optiriego para optimizar el manejo del riego en uva vinífera (Startup Ciencia 2026) | F42: Programa Nacional de Producción Vegetal | G42: MARTINEZ CASTILLO, JUAN PABLO | H42: YUMMY TECH LIMITADA | I42: 1472 | J42: Postulado | K42: Si | M42: En concurso
B43: 45874 | C43: IDeA I+D 2026 | D43: Rayentué | E43: Desarrollo y validación de modelos de predicción genómica en cerezo para una selección anticipada y precisa de nuevas variedades | F43: Programa Nacional de Producción Vegetal | G43: DONOSO CONTRERAS, JOSE MANUEL | H43: UCHILE - Universidad de Chile | I43: 1467 | J43: Postulado | K43: Si | M43: En concurso
A44: 13 | B44: 45860 | C44: Convocatoria Nacional Proyectos de Innovación para el Agro 2025-2026 FIA-Propuesta completa | D44: Rayentué | E44: Herramienta digital para la inspección de pulverizadores hidroneumáticos utilizados en huertos frutales | F44: Programa Nacional de Producción Vegetal | G44: ABARCA REYES, LUIS PATRICIO | H44: INIA | I44: 1444 | J44: Postulado | K44: Si | L44: No | M44: En concurso
...

Sheet Pys Post.
D3: PROYECTOS POSTULADOS RAYENTUÉ
C8: Añode adjudicación | D8: Año Postulación2 | E8: Fuente Financiamiento | F8: Concurso o Linea | G8: CRI | H8: Titulo Proyecto | I8: Programas Nacionales | J8: Investigador/a Encargado/a | K8: Ejecutor Principal | L8: Estado | M8: ID- PERFIL | N8: Fecha de Postulación | O8: Monto solicitado | P8: Asociado Pecuniario | Q8: Asociado No Pecuniario | R8: Inia Pecuniario | S8: Inia No Pecuniario | T8: Costo Total del Proyecto | U8: Rendible a la FF | V8: Libre disposición (overhead) | W8: Duración (meses) | X8: Fecha de Aprobación | Y8: Condiciones de aprobación | Z8: Fecha de Rechazo | AA8: Motivos rechazo | AB8: Fuente de Información (Acta resolución) | AC8: Codigo Proyecto Fuente financ. | AD8: Observaciones | AE8: Monto adjudicado | AF8: Monto contrapartida | AG8: Monto aporte INIA | AH8: Monto capturado po INIA | AI8: Costo Total del proyecto4
C9: FECHA ACTUALIZACIÓN | F9: 45790
C10: RESPONSABLE | F10: Christian Núñez Berrios
O11: Ficha financiera
P12: Monto contrapartida (asociados) | R12: Monto aporte INIA | U12: Monto capturado por INIA (Gastos de Administración) | AE12: Modificaciones al presupuesto solicitado
C13: Añode adjudicación | D13: Año Postulación2 | E13: Fuente Financiamiento | F13: Concurso o Linea | G13: CRI | H13: Titulo Proyecto | I13: Programas Nacionales | J13: Investigador/a Encargado/a | K13: Ejecutor Principal | L13: Estado | M13: ID- PERFIL | N13: Fecha de Postulación | O13: Monto solicitado | P13: Asociado Pecuniario | Q13: Asociado No Pecuniario | R13: Inia Pecuniario | S13: Inia No Pecuniario | T13: Costo Total del Proyecto | U13: Rendible a la FF | V13: Libre disposición (overhead) | W13: Duración (meses) | X13: Fecha de Aprobación | Y13: Condiciones de aprobación | Z13: Fecha de Rechazo | AA13: Motivos rechazo | AB13: Fuente de Información (Acta resolución) | AC13: Codigo Proyecto Fuente financ. | AD13: Observaciones | AE13: Monto adjudicado | AF13: Monto contrapartida | AG13: Monto aporte INIA | AH13: Monto capturado po INIA | AI13: Costo Total del proyecto4
D14: =+Tabla2[[#This Row],[Fecha de Postulación]] -> 44414 | E14: Contratos Privados Internacionales | F14: FONTAGRO | G14: ='Perfiles '!D57 -> 16-Rayentué | H14: Agtechmetro | I14: Agrosistemas Sustentables | J14: FELMER ECHEVERRIA, SOFIA | K14: U. AUSTRAL | L14: RECHAZADO | M14: Sin Información | N14: 44414 | O14: No tengo la info | P14: 0 | Q14: 0 | R14: 0 | S14: 0 | T14: =SUM(O14:S14) -> 0 | U14: No tengo la info | V14: No tengo la info | W14: No tengo la info | X14: RECHAZADO | Y14: N/A | Z14: 44505 | AA14: Puntuación baja 62,67/100 y requería como minimo 75/100 | AB14: Carta FTG/6935 de fecha 5 de noviembre de 2021 | AC14: 584
C15: 2019 | D15: =+Tabla2[[#This Row],[Fecha de Postulación]] -> 43776 | E15: FONDEQUIP | F15: X Concurso de Equipamiento Científico y Tecnológico-FONDEQUIP, Región de O’Higgins, año 2019 | G15: 16-Rayentue, 20-Quilamapu, 13-La Cruz | H15: Desarrollo de una plataforma de análisis de fragmentos y secuencias de ADN para fortalecer el desarrollo científico y tecnológico de la Región de O'Higgins | I15: Producción Vegetal | J15: SAGREDO DIAZ, BORIS | K15: INIA | L15: ADJUDICADO | M15: Sin Información | N15: 43776 | O15: 90000000 | P15: 3700000 | Q15: 0 | R15: 4500000 | S15: 22427400 | T15: =SUM(O15:S15) -> 120627400 | U15: 0 | V15: 0 | W15: 18 | X15: 44174 | Z15: N/A | AA15: N/A | AB15: Res. Exento N°12525/2020 | AC15: EQUR190005 | AE15: 90000000 | AF15: 1500000 | AG15: 26927400 | AH15: 0 | AI15: =AE15+AF15+AG15 -> 118427400
C16: 2019 | D16: =+Tabla2[[#This Row],[Fecha de Postulación]] -> 43776 | E16: CONICYT | F16: Anillos de Investigación en Ciencia Y tecnología para la Región de O´Higgins 2019 | G16: 16-Rayentué | H16: Deep insight in the cherry plant defense responses to bacterial canker disease in a scenario of water restriction | I16: Producción Vegetal | J16: SAGREDO DIAZ, BORIS | K16: UOH | L16: ADJUDICADO | M16: Sin Información | N16: 43776 | O16: 112500000 | P16: 0 | Q16: 0 | R16: 0 | S16: 57780300 | T16: =SUM(O16:S16) -> 170280300 | U16: 0 | V16: 0 | W16: 36 | X16: 44096 | Z16: N/A | AA16: N/A | AB16: Res. Exenta N°10451/2020 | AE16: 32697647 | AF16: 0 | AG16: 57780349 | AH16: 0 | AI16: =AE16+AF16+AG16 -> 90477996
D17: =+Tabla2[[#This Row],[Fecha de Postulación]] -> 43755 | E17: FONDEF | F17: VIII Concurso de Investigación Tecnológica 2019-IDeA | G17: 16-Rayentue | H17: Validación de la tecnología de nanoburbujas en distintos niveles de la cadena de producción de fruta fresca | I17: Producción Vegetal | J17: OTAROLA ALIAGA, JAIME IGNACIO | K17: INIA | L17: RECHAZADO | M17: Sin Información | N17: 43755 | O17: 188241000 | P17: 60000000 | Q17: 0 | R17: 0 | S17: 39556000 | T17: =SUM(O17:S17) -> 287797000 | U17: 21850000 | V17: 0 | W17: 24 | X17: =L17 -> RECHAZADO | Y17: N/A | Z17: 43847 | AA17: Nota 2,6 | AB17: Informe de Evaluación recibido por mail
C18: 2019 | D18: =+Tabla2[[#This Row],[Fecha de Postulación]] -> 43732 | E18: FONDECYT | F18: FONDECYT DE POSTDOCTORADO 2020 | G18: 16-Rayentue, 15-Hidango, 20-Quilamapu, 14-Los Tilos | H18: DETERMINACIÓN DE LAS BASES FISIOLÓGICAS DE LA ADAPTACIÓN DE GENOTIPOS DE TRIGO CANDEAL DE INIA A CONDICIONES DE SEQUÍA EN EL SECANO MEDITERRÁNEO DE CHILE | I18: Producción Vegetal | J18: ALFARO JARA, CHRISTIAN EUGENIO | K18: INIA | L18: ADJUDICADO | M18: Sin Información | N18: 43732 | O18: 0 | P18: 0 | Q18: 0 | R18: 0 | S18: 13262000 | T18: =SUM(O18:S18) -> 13262000 | U18: 0 | V18: 0 | W18: 36 | X18: 43902 | Z18: N/A | AA18: N/A | AB18: Carta N°018/FONDECYT/UGC/189 | AC18: 3200742 | AE18: 0 | AF18: 0 | AG18: 13262000 | AH18: 0 | AI18: =AE18+AF18+AG18 -> 13262000
D19: =+Tabla2[[#This Row],[Fecha de Postulación]] -> 43707 | E19: INNOVA-CORFO | F19: Bienes Públicos 2019- Temática "Adaptación al Cambio Climático" | G19: 16-RAYENTUE | H19: Adaptación al manejo agronómico del cultivo de cerezo desarrollado bajo cubiertas plásticas | I19: Producción Vegetal | J19: OTAROLA ALIAGA, JAIME IGNACIO | K19: INIA | L19: RECHAZADO | M19: Sin Información | N19: 43707 | O19: 100202000 | P19: 15990000 | Q19: 0 | R19: 5100000 | S19: 17755000 | T19: =SUM(O19:S19) -> 139047000 | U19: =O19+P19+R19 -> 121292000 | V19: 0 | W19: 36 | X19: =L19 -> RECHAZADO | Y19: N/A | Z19: 43741 | AA19: No es pertinente | AB19: Oficio N°02804 | AC19: 19BP-117383 | AD19: numeral 12.2 de las bases, se concluyó que su proyecto no cumplió con todos los requisitos de dicho análisis y, por lo tanto, es no pertinente
D20: =+Tabla2[[#This Row],[Fecha de Postulación]] -> 43682 | E20: FNDR O'Higgins | F20: Fondos 2020 | G20: 16-Rayentue | H20: Diseño Ampliación edificio INIA | I20: No aplica | J20: BARTEL CLAUDIA | K20: INIA | L20: OT | M20: Sin Información | N20: 43682 | O20: 12285000 | P20: 0 | Q20: 0 | R20: 0 | S20: 0 | T20: =SUM(O20:S20) -> 12285000 | W20: 10 | X20: NO SE SIGUIO CON LOS PROCESOS MOP, CORES, INTENDENTE | Y20: RS | AC20: Código BIP : 40013817 | AI20: =AE20+AF20+AG20 -> 0
D21: =+Tabla2[[#This Row],[Fecha de Postulación]] -> 43620 | E21: CONICYT | F21: Concurso Regular Fondecyt 2020 | G21: 14-LOS TILOS, 16-RAYENTUE, 10-LA PLATINA, 05-INTIHUASI | H21: Disentangling the epigenetic influence on fruit development and ripening in three stone fruits Prunus species | I21: Producción Vegetal | J21: DONOSO CONTRERAS JOSE MANUEL | K21: UCH | L21: Rechazado | M21: Sin Información | N21: 43620 | O21: 3664000 | P21: 0 | Q21: 0 | R21: 0 | S21: 9650000 | T21: =SUM(O21:S21) -> 13314000 | U21: 0 | V21: 0 | W21: 48 | X21: 21-12-2019 | Z21: N/A | AA21: N/A | AB21: Respuesta enviada a UCH | AE21: 3664000 | AF21: 0 | AG21: 9650000 | AH21: 0 | AI21: =AE21+AF21+AG21 -> 13314000
D22: =+Tabla2[[#This Row],[Fecha de Postulación]] -> 43616 | E22: CONICYT | F22: PCI ECOS CONICYT Concurso de proyectos de intercambio Chile Francia 2019 | G22: 14-LOS TILOS, 10-LA PLATINA, 16-RAYENTUE | H22: Collaborative counter season research efforts between France and Chile analysis of traits affected by climate change in sweet cherry in order to create new varieties adapted to future environmental conditions | I22: Producción Vegetal | J22: DONOSO CONTRERAS JOSE MANUEL | K22: INIA | L22: RECHAZADO | M22: Sin Información | N22: 43616 | O22: 12900000 | P22: 0 | Q22: 0 | R22: 0 | S22: 250000 | T22: =SUM(O22:S22) -> 13150000 | W22: 36 | X22: RECHAZADO | Y22: N/A | Z22: 43936
D23: =+Tabla2[[#This Row],[Fecha de Postulación]] -> 43396 | E23: CONICYT | F23: Concurso Postdoctorado 2019 | G23: 16-RAYENTUE | H23: INTERACCIÓN G X E DE CARACTERES MORFO-FISIOLÓGICOS DE ADAPTACIÓN A CONDICIONES DE SEQUÍA Y SU EFECTO EN LA DETERMINACIÓN DEL RENDIMIENTO EN TRIGO CANDEAL. Marcela Opazo - opazo.marcela@gmail.com | I23: Producción Vegetal | J23: ALFARO JARA, CHRISTIAN EUGENIO | K23: INIA | L23: RECHAZADO | M23: Sin Información | N23: 43396 | O23: 0 | P23: 0 | Q23: 17000000 | R23: 17000000 | S23: 0 | T23: =SUM(O23:S23) -> 34000000 | W23: 36 | X23: RECHAZADO | Y23: CARTA DIRIGIDA A MARCELA OPAZO, INVESTIGADORA PPAL. | Z23: 43535 | AA23: QUEDARON ABAJO DEL PUNTAJE DE CORTE
D24: =+Tabla2[[#This Row],[Fecha de Postulación]] -> 43347 | E24: FONDECYT | F24: Concurso Regular Fondecyt 2019 | G24: 16-RAYENTUE | H24: HYDRAULIC MECHANISMS AND CARBON METABOLISM IN THE ADAPTATION OF WHEAT TO CONDITIONS OF CLIMATE CHANGE IN SEVERE DROUGHT MEDITERRANEAN ENVIRONMENTS/ MECANISMOS HIDRAULICOS Y DE METABOLISMO DEL CARBONO EN LA ADAPTACION DEL CULTIVO DE TRIGO A CONDICIONES DE CAMBIO CLIMÁTICO EN AMBIENTES DE SEQUIA SEVERA DE TIPO MEDITERRANEO | I24: Producción Vegetal | J24: ALFARO JARA, CHRISTIAN EUGENIO | K24: U. Chile | L24: RECHAZADO | M24: Sin Información | N24: 43347 | O24: 25400000 | P24: 0 | Q24: 10000000 | R24: 35400000 | T24: =SUM(O24:S24) -> 70800000 | W24: 48 | X24: RECHAZADO | Y24: carta N°018/Fondecyt/22 | Z24: 43543 | AA24: puntaje
C25: 2018 | D25: =+Tabla2[[#This Row],[Fecha de Postulación]] -> 43291 | E25: FNDR Antofagasta | F25: Fondos 2019 | G25: 16-Rayentué | H25: Tranferencia Control Mostaza negra -El Loa | I25: Agrosistemas Sustentables | J25: VEGA CANDIA, BARBARA CHANTAL | K25: INIA | L25: ADJUDICADO | M25: Sin Información | N25: 43291 | O25: 1028356000 | P25: 0 | Q25: 29540000 | R25: 0 | S25: 70754000 | T25: =SUM(O25:S25) -> 1128650000 | U25: 48969000 | W25: 36 | X25: 17-09-2019 | Z25: N/A | AA25: N/A | AB25: Acuerdo CORE 15352-19 | AC25: Cod. BIP. 40002794-0 | AE25: 1028356000 | AF25: 29540000 | AG25: 70754000 | AH25: 0 | AI25: =AE25+AF25+AG25 -> 1128650000
D26: 46087 | E26: Corporación Nacional Forestal | F26: XVII Concurso Fondo de Investigación del Bosque Nativo-CONAF 2026 | G26: 16-RAYENTUE | H26: Restauración de bosques fragmentados del secano costero de la Región de O’Higgins mediante el uso de especies nodrizas leñosas y cactáceas nativas | I26: Programa Nacional de Agrosistemas Sustentables | J26: CACERES CELEDON, EMILIO JOSE | K26: INIA | L26: En concurso | M26: 1617 | N26: 46087 | O26: 75000000 | P26: 0 | Q26: 2692825 | R26: 0 | S26: 64944210 | T26: =SUM(O26:S26) -> 142637035
D27: 46100 | E27: ANID | F27: Concurso de Investigación Tecnológica IDeA 2026 | G27: 16-RAYENTUE | H27: Hacia un control mas sustentable del cáncer bacterial en cerezos: reducción del uso de cobre y pérdidas productivas mediante herramientas biotecnológicas y monitoreo molecular predictivo | I27: Programa Nacional de Producción Vegetal | J27: SAGREDO DIAZ, BORIS | K27: INIA | L27: En concurso | M27: 1615 | N27: 46100 | O27: 237000000 | P27: 23700000 | Q27: 47400000 | R27: 100518777 | S27: 0 | T27: =SUM(O27:S27) -> 408618777
D28: 45944 | E28: INNOVA-CORFO | F28: Viraliza Eventos 2025 | G28: Rayentué | H28: Viraliza Agro Tech O’Higgins (Viraliza Eventos 2025) | I28: Programa Nacional de Agrosistemas Sustentables | J28: AGUIRRE AGUILERA, CRISTIAN | K28: UOH - Universidad de O'Higgins | L28: Adjudicado | M28: 1553 | N28: 45951 | O28: 0 | P28: 0 | Q28: 0 | R28: 0 | S28: 3574816 | T28: =SUM(O28:S28) -> 3574816 | U28: 0 | V28: 0 | W28: 8
D29: 45901 | E29: FIA | F29: Consultorías Regionales para la Innovación 2025 | G29: Rayentué | H29: Gestión eficiente del agua de riego de Convento Viejo 2: diagnóstico de suelos, riego y cultivos en las comunas de Lolol, Pumanque y Marchigue | I29: Programa Nacional de Agrosistemas Sustentables | J29: CACERES CELEDON, EMILIO JOSE | K29: INIA | L29: Adjudicado | M29: 1523 | N29: 45937 | O29: 10000000 | P29: 500000 | Q29: 0 | R29: 0 | S29: 25763869 | T29: =SUM(O29:S29) -> 36263869 | V29: 0 | W29: 9
D30: 45901 | E30: FIA | F30: Giras nacionales de innovación para Mujeres Agroinnovadoras 2025 | G30: Rayentué | H30: Raíces femeninas: Gira agroecológica de mujeres transformadoras | I30: Programa Nacional de Agrosistemas Sustentables | J30: VEGA CANDIA, BARBARA CHANTAL | K30: INIA | L30: No adjudicado | M30: 1522 | N30: 45937 | O30: 14629621 | P30: 0 | Q30: 0 | R30: 250000 | S30: 1416288 | T30: =SUM(O30:S30) -> 16295909 | V30: 0 | W30: 1
D31: 45886 | E31: ANID | F31: Startup Ciencia 2026 | G31: Rayentué | H31: Optiriego Plus: Aceleramiento del desarrollo tecnológico y comercial del sensor Optiriego para optimizar el manejo del riego en uva vinífera (Startup Ciencia 2026) | I31: Programa Nacional de Producción Vegetal | J31: MARTINEZ CASTILLO, JUAN PABLO | K31: YUMMY TECH LIMITADA | L31: Postulado | M31: 1472 | N31: 45910 | O31: 20971432 | P31: 16877582 | Q31: 30000000 | R31: 0 | S31: 30299906 | T31: =SUM(O31:S31) -> 98148920 | U31: 0 | V31: 0 | W31: 12
D32: 45874 | E32: ANID | F32: IDeA I+D 2026 | G32: Rayentué | H32: Desarrollo y validación de modelos de predicción genómica en cerezo para una selección anticipada y precisa de nuevas variedades | I32: Programa Nacional de Producción Vegetal | J32: DONOSO CONTRERAS, JOSE MANUEL | K32: UCHILE - Universidad de Chile | L32: En concurso | M32: 1467 | N32: 45930 | O32: 46964800 | P32: 0 | Q32: 68859600 | R32: 0 | S32: 38923792 | T32: =SUM(O32:S32) -> 154748192 | V32: 6831000 | W32: 24
D33: 45860 | E33: FIA | F33: Convocatoria Nacional Proyectos de Innovación para el Agro 2025-2026 FIA-Propuesta completa | G33: Rayentué | H33: Herramienta digital para la inspección de pulverizadores hidroneumáticos utilizados en huertos frutales | I33: Programa Nacional de Producción Vegetal | J33: ABARCA REYES, LUIS PATRICIO | K33: INIA | L33: No adjudicado | M33: 1444 | N33: 45860 | O33: 149890000 | P33: 1000000 | Q33: 840000 | R33: 300000 | S33: 59106880 | T33: =SUM(O33:S33) -> 211136880 | V33: 10440000
D34: 45860 | E34: FIA | F34: Convocatoria Nacional Proyectos de Innovación para el Agro 2025-2026 FIA-Propuesta completa | G34: Rayentué | H34: Gestión sostenible del rendimiento y calidad del trigo en el secano interior de sequía severa en la Región de O'Higgins, aumentando la EUA y EUN. | I34: Programa Nacional de Producción Vegetal | J34: RUBILAR TORRES, FELIPE ANDRES | K34: UCHILE - Universidad de Chile | L34: No adjudicado | M34: 1412 | N34: 45860 | O34: 50389000 | P34: 0 | Q34: 0 | R34: 0 | S34: 26854376 | T34: =SUM(O34:S34) -> 77243376 | V34: 0
D35: 45860 | E35: FIA | F35: Convocatoria Nacional Proyectos de Innovación para el Agro 2025-2026 FIA-Propuesta completa | G35: Rayentué | H35: Optimización del manejo y diseño de invernaderos hortícolas mediante una plataforma de monitoreo ambiental en la Región de O’Higgins | I35: Programa Nacional de Producción Vegetal | J35: MARTINEZ CASTILLO, JUAN PABLO | K35: INIA | L35: No adjudicado | M35: 1395 | N35: 45860 | O35: 119473199 | P35: 7000000 | Q35: 25973914 | R35: 0 | S35: 36416048 | T35: =SUM(O35:S35) -> 188863161 | V35: 8328000
D36: 45860 | E36: FIA | F36: Convocatoria Nacional Proyectos de Innovación para el Agro 2025-2026 FIA-Propuesta completa | G36: Rayentué | H36: Estrategias para mitigar el daño por piel de lagarto en cerezas de exportación | I36: Programa Nacional de Producción Vegetal | J36: DONOSO CONTRERAS, JOSE MANUEL | K36: INIA | L36: Adjudicado | M36: 1388 | N36: 45860 | O36: 149624480 | P36: 6000000 | Q36: 13800000 | R36: 0 | S36: 50361000 | T36: =SUM(O36:S36) -> 219785480 | V36: 9435020
D37: 45860 | E37: FIA | F37: Convocatoria Nacional Proyectos de Innovación para el Agro 2025-2026 FIA-Propuesta completa | G37: Rayentué | H37: Validación de un modelo de alerta preventiva contra los principales hongos de madera que afectan al cultivo del cerezo para mantener los estándares de calidad y competitividad en el mercado | I37: Programa Nacional de Producción Vegetal | J37: OTAROLA ALIAGA, JAIME IGNACIO | K37: INIA | L37: Adjudicado | M37: 1387 | N37: 45860 | O37: 149784006 | P37: 8000000 | Q37: 0 | R37: 1000000 | S37: 77389479 | T37: =SUM(O37:S37) -> 236173485 | V37: 10400000
D38: 45832 | E38: FONDECYT | F38: Fondecyt Regular 2026 | G38: Rayentué | H38: Disentangling the epigenetic influence on differentiation of fruit development between early and late varieties in sweet cherry (Prunus avium) | I38: Programa Nacional de Producción Vegetal | J38: DONOSO CONTRERAS, JOSE MANUEL | K38: UCHILE - Universidad de Chile | L38: No adjudicado | M38: 1363 | N38: 45832 | O38: 10730000 | P38: 0 | Q38: 0 | R38: 0 | S38: 7360706 | T38: =SUM(O38:S38) -> 18090706 | U38: 0
D39: 45832 | E39: FONDECYT | F39: Fondecyt Regular 2026 | G39: Rayentué | H39: Improving salinity tolerance in ‘Old Limachino Tomato’ through grafting onto two clonal rootstocks derived from reciprocal interspecific crosses between cultivated and wild tomato genotypes | I39: Programa Nacional de Producción Vegetal | J39: MARTINEZ CASTILLO, JUAN PABLO | K39: INIA | L39: Adjudicado | M39: 1362 | N39: 45832 | O39: 271644000 | P39: 0 | Q39: 0 | R39: 0 | S39: 148519718 | T39: =SUM(O39:S39) -> 420163718 | U39: 45274000 | V39: 0
D40: =+Tabla2[[#This Row],[Fecha de Postulación]] -> 45777 | E40: FONDECYT | F40: Fondecyt de Iniciación en Investigación 2026 | G40: 16-Rayentué | H40: Identification of stable and heritable physiological traits for the selection of drought-tolerant quinoa (Chenopodium quinoa Willd.) genotypes under drought environments | I40: Producción Vegetal | J40: ESTRADA BRAVO, FELIX RODOLFO | K40: INIA | L40: No adjudicado | M40: 1303 | N40: 45777 | O40: 104400000 | P40: 0 | Q40: 0 | R40: 0 | S40: 63067518 | T40: =SUM(O40:S40) -> 167467518 | U40: 14400000 | V40: 0 | W40: 36
D41: =+Tabla2[[#This Row],[Fecha de Postulación]] -> 45736 | E41: FONDEF | F41: Concurso de Investigación Tecnológica IDeA 2025 | G41: 16-Rayentué | H41: GENERANDO INFORMACIÓN CLAVE PARA EL DESARROLLO DE ESTRATEGIAS SUSTENTABLES DE CONTROL DEL CANCER BACTERIAL EN CEREZOS: BASADOS EN LAS CARACTERÍSTICAS DE LA POBLACIÓN DEL AGENTE CAUSAL | I41: Producción Vegetal | J41: SAGREDO DIAZ, BORIS | K41: INIA | L41: No adjudicado | M41: 1267 | N41: 45736 | O41: 237000000 | P41: 0 | Q41: 71100001 | R41: 0 | S41: 111029264 | T41: =SUM(O41:S41) -> 419129265 | U41: 28000000 | V41: 0 | W41: 24
D42: 45622 | E42: FIA | F42: Convocatoria Nacional Proyectos de Innovación para el agro con Énfasis Regional 2024-2025 FIA | G42: 16-Rayentué | H42: Desarrollo de estrategias de riego deficitario controlado en diferentes variedades de cerezos y zonas agroclimáticas de Chile con baja disponibilidad hídrica. | I42: Programa Nacional de Agrosistemas Sustentables | J42: CACERES CELEDON, EMILIO JOSE | K42: INIA | L42: No adjudicado | M42: 1213 | N42: 45622 | O42: 150000000 | P42: 5000000 | Q42: 5000000 | R42: 0 | S42: 83701088 | T42: =SUM(O42:S42) -> 243701088 | V42: 5 | W42: 36
D43: 45622 | E43: FIA | F43: Convocatoria Nacional Proyectos de Innovación para el agro con Énfasis Regional 2024-2025 FIA | G43: 16-Rayentué | H43: Empaquetamiento técnico y comercial de la primera variedad de cereza chilena para un mercado de alta exigencia en calidad | I43: Producción Vegetal | J43: OTAROLA ALIAGA, JAIME IGNACIO | K43: INIA | L43: Adjudicado | M43: 1209 | N43: 45622 | O43: 119808000 | P43: 2000000 | Q43: 0 | R43: 0 | S43: 52719999 | T43: =SUM(O43:S43) -> 174527999 | U43: 8300000 | W43: 36
D44: 45626 | E44: FRPD | F44: Fondo Regional para la Productividad y el Desarrollo (FRPD)- Región de O'Higgins 2024 | G44: 16-Rayentué | H44: Desarrollo de la agricultura urbana y periurbana como alternativa de desarrollo sostenible para la producción de alimentos en la Región de O`Higgins. | I44: Programa Nacional de Agrosistemas Sustentables | J44: RUBILAR TORRES, FELIPE ANDRES | K44: INIA | L44: Adjudicado | M44: 1165 | N44: 45626 | O44: 203909000 | P44: 10200000 | Q44: 1000000 | R44: 0 | S44: 9193390 | T44: =SUM(O44:S44) -> 224302390 | U44: 10000000 | W44: 36
D45: 45626 | E45: FRPD | F45: Fondo Regional para la Productividad y el Desarrollo (FRPD)- Región de O'Higgins 2024 | G45: 16-Rayentué | H45: Transferencia de un paquete tecnológico para el control de ataques de depredadores en ovinos del secano costero de O’Higgins. | I45: Programa Nacional de Producción Animal | J45: QUEZADA JARA, MARCELO | K45: INIA | L45: Adjudicado | M45: 1163 | N45: 45626 | O45: 280000000 | P45: 15000000 | Q45: 0 | R45: 0 | S45: 21085437 | T45: =SUM(O45:S45) -> 316085437 | U45: 13720000 | W45: 36
D46: 45576 | E46: FRPD | F46: Fondo Regional para la Productividad y el Desarrollo (FRPD)- Región de O'Higgins 2024 | G46: 16-Rayentué | H46: Transferencia del diagnóstico y manejo integrado de enfermedades del almendro: estrategias innovadoras para aumentar la competitividad del cultivo en la región de ohiggins | I46: Programa Nacional de Agrosistemas Sustentables | J46: RIQUELME TOLEDO, DANAE | K46: INIA | L46: Adjudicado | M46: 1162 | N46: 45626 | O46: 280000000 | P46: 14000000 | Q46: 0 | R46: 0 | S46: 138674506 | T46: =SUM(O46:S46) -> 432674506 | U46: 14000000 | V46: 0 | W46: 36
...

Sheet Pys Privados-12 y ADirecta Publ
M1: Monto contrapartida (asociados) | O1: Monto aporte INIA | R1: Monto capturado por INIA (Gastos de Administración) | AB1: Modificaciones al presupuesto solicitado
B2: Año Postulación | C2: Fuente Financiamiento | D2: Concurso o Linea | E2: CRI | F2: Titulo Proyecto | G2: Programas Nacionales | H2: Investigador/a Encargado/a | I2: Ejecutor Principal | J2: Estado | K2: Fecha de Postulación | L2: Monto solicitado | M2: Pecuniario | N2: No Pecuniario | O2: Pecuniario | P2: No Pecuniario | Q2: Costo Total del Proyecto | R2: Rendible a la FF | S2: Libre disposición (overhead) | T2: Duración (meses) | U2: Fecha de Aprobación | V2: Condiciones de aprobación | W2: Fecha de Rechazo | X2: Motivos rechazo | Y2: Fuente de Información (Acta resolución) | Z2: Codigo Proyecto Fuente financ. | AA2: Observaciones | AB2: Monto adjudicado | AC2: Monto contrapartida | AD2: Monto aporte INIA | AE2: Monto capturado po INIA | AF2: Costo Total del proyecto
B3: 2023 | C3: Municipalidad de Pichidegua | D3: Contrato Municipalidad | E3: 16-Rayentue | F3: Convenio de Colaboración Técnica y Transferencia Tecnológica INIA - Municipalidad de Pichidegua | G3: Producción Vegetal | H3: Bárbara Vega | I3: INIA | J3: Convenio firmado | K3: 45043 | L3: 5000000 | P3: 3442711 | Q3: =+L3+P3 -> 8442711 | R3: 0 | S3: 210084 | T3: 7 | U3: 45077
B4: 2025 | C4: Bioamerica | D4: CONTRATO PRIVADO | E4: 16-Rayentue | F4: CONTRATO DE PRESTACION DE SERVICIOS ENTRE INSTITUTO DE INVESTIGACIONES AGROPECUARIAS (INIA) Y BIOAMERICA S.A | G4: Producción Vegetal | H4: OTAROLA ALIAGA, JAIME IGNACIO | I4: INIA | J4: Convenio Firmado Inia | K4: 45689 | L4: 8901933 | P4: 8743845 | Q4: =+L4+P4 -> 17645778 | T4: 17
B5: 2023 | C5: Innovak Global Chile SpA | D5: CONTRATO PRIVADO | E5: 16-Rayentue | F5: Addendum Contrato de Trabajo | G5: Agrosistemas Sustentables | H5: CARRASCO JIMENEZ JORGE | I5: INIA | J5: Convenio firmado | K5: 44986 | L5: 10612500 | M5: 0 | N5: 0 | O5: 0 | P5: 14671736 | Q5: =SUM(L5:P5) -> 25284236 | R5: 0 | S5: 2540075 | T5: 10 | U5: 44986 | AA5: Renovación contrato
B6: 2024 | C6: Municipalidad de San Pedro | D6: Contrato Municipalidad | E6: 16-Rayentue | F6: Convenio de Colaboración INIA y Municipalidad de San Pedro Difusión de tecnologías de cultivos de trigo y triticale | G6: Producción Vegetal | H6: Cristian Aguirre | I6: INIA | J6: Convenio firmado | K6: 45565 | L6: 12000000 | Q6: =SUM(L6:P6) -> 12000000
B7: 2022 | C7: Municipalidad de San Pedro | D7: Contrato Municipalidad | E7: 16-Rayentue | F7: Convenio de Colaboración INIA y Municipalidad de San Pedro Difusión de tecnologías de cultivos de trigo y triticale | G7: Producción Vegetal | H7: Cristian Aguirre | I7: INIA | J7: Convenio firmado | K7: 44921 | L7: 10559833 | M7: 0 | N7: 0 | O7: 0 | P7: 1498447 | Q7: =SUM(L7:P7) -> 12058280 | R7: 0 | S7: 527991 | T7: 12 | U7: 44921
B8: 2022 | C8: NESTLÉ | D8: CONTRATO PRIVADO | E8: 16-Rayentue | F8: Implementación de prácticas de Agricultura Regenerativa en cultivos de trigo | G8: Producción Vegetal | H8: Christian Alfaro (cambia a Iván Matus de Quilamapu) | I8: INIA | J8: Convenio en revisión para firma | K8: 44805 | L8: 126000000 | M8: 0 | N8: 0 | O8: 0 | P8: 54427996 | Q8: =SUM(L8:P8) -> 180427996 | R8: 0 | S8: 17379000 | T8: 36 | U8: 44894
B9: 2022 | C9: Municipalidad San Vicente de Tagua Tagua | D9: Contrato Municipalidad | E9: 16-Rayentue | F9: Convenio de Asistencia Técnica y Transferencia Tecnológica INIA - San Vicente de Tagua Tagua | G9: Extensión y Formación de capacidades | H9: Bárbara Vega | I9: INIA | J9: Convenio firmado | K9: 44846 | L9: 21325500 | M9: 0 | N9: 0 | O9: 0 | P9: 7500000 | Q9: =SUM(L9:P9) -> 28825500 | R9: 1066275 | S9: 0 | T9: 15 | U9: 44846
B10: 2022 | C10: Municipalidad Quinta Tilcoco | D10: Contrato Municipalidad | E10: 16-Rayentue | F10: Programa GET Agroecológico de producción de hortalizas con inclusión de capacidades diferentes | G10: Extensión y Formación de capacidades | H10: Bárbara Vega | I10: INIA | J10: Convenio firmado | K10: 44708 | L10: 3444000 | M10: 0 | N10: 0 | O10: 0 | P10: 10126994 | Q10: =SUM(L10:P10) -> 13570994 | R10: 172000 | S10: 0 | T10: 12 | U10: 44748
B11: 2021 | C11: VIÑA LUIS FELIPE EDUARDS | D11: CONTRATO PRIVADO | E11: 16-Rayentue | F11: Evaluación Riego por pulso | G11: Agrosistemas Sustentables | H11: FELMER ECHEVERRIA, SOFIA | I11: INIA | J11: EN EVALUACION
B12: 2021 | C12: AGROSUPER | D12: CONTRATO PRIVADO | E12: 16-Rayentue | F12: evaluación de compost | G12: Agrosistemas Sustentables | H12: CARRASCO JIMENEZ JORGE | I12: INIA | J12: EN EVALUACION
B13: 2021 | C13: USACH | D13: CONTRATO PRIVADO | E13: 16-Rayentue | F13: Granos tradicionales para la seguridad alimentaria | G13: Producción Vegetal | H13: ALFARO JARA, CHRISTIAN EUGENIO | I13: USACH | J13: EN REDACCION DEL CONTRATO
B14: 2021 | C14: BIOAMERICA | D14: CONTRATO PRIVADO | E14: 16-Rayentue | F14: Efecto del producto ERGER 2 como quebrador de dormancia en cerezos (Prunus avium) var. Lapins | G14: Frutales | H14: OTAROLA ALIAGA, JAIME IGNACIO | I14: INIA | J14: APROBADO
B15: 2021 | C15: INNOVATEK | D15: CONTRATO PRIVADO | E15: 16-Rayentue | F15: evaluación del floculante de suelos Promesol 5X, | G15: Agrosistemas Sustentables | H15: CARRASCO JIMENEZ JORGE | I15: INIA | J15: APROBADO
B16: 2020 | C16: FIC | D16: CONTRATO PRIVADO | E16: 16-Rayentue | F16: Transferencia tecnológica PAFAM | G16: Producción Vegetal | H16: ALFARO JARA, CHRISTIAN EUGENIO | I16: UOH | J16: RECHAZADO | T16: 36 | U16: En concurso / paso Admisibilidad/ paso Ev Tecnica
B17: 2020 | C17: ASCC | D17: CONTRATO PRIVADO | E17: 16-Rayentue | F17: Programa APL Agroecología | G17: UPSE | H17: BARTEL CLAUDIA | I17: INIA | J17: EN POSTULACION CON V°B° FIC | L17: 151575000 | M17: 42666667
B18: 2020 | C18: Municipalidad Quinta Tilcoco | D18: CONTRATO PRIVADO | E18: 16-Rayentue | F18: GTT Agroecológico de Producción de Hortalizas con inclusión de capacidades diferentes | H18: VEGA BARBARA | I18: INIA | J18: APROBADO | L18: 2120842 | P18: 10920954 | AB18: 2120790

Sheet Analisis pymay25
A3: Añode adjudicación | B3: (Todas)
A5: Suma de Costo Total del Proyecto | B5: Etiquetas de columna
A6: Etiquetas de fila | B6: Adjudicado | C6: En Concurso | D6: No adjudicado | E6: OT | F6: RECHAZADO | G6: (en blanco) | H6: Total general
A7: Anid | B7: 767845544 | C7: 475886646 | D7: 282718815 | F7: 411910000 | H7: 1938361005
A8: ALFARO JARA, CHRISTIAN EUGENIO | D8: 127589000 | H8: 127589000
A9: MARTINEZ CASTILLO, JUAN PABLO | B9: 45574372 | C9: 475886646 | D9: 86243575 | H9: 607704593
A10: SAGREDO DIAZ, BORIS | B10: 722271172 | D10: 68886240 | F10: 411910000 | H10: 1203067412
A11: CONICYT | B11: 170280300 | F11: 66364000 | H11: 236644300
A12: ALFARO JARA, CHRISTIAN EUGENIO
A13: DONOSO CONTRERAS JOSE MANUEL | F13: 28864000 | H13: 28864000
A14: SAGREDO DIAZ, BORIS | B14: 170280300 | F14: 37500000 | H14: 207780300
A15: Contratos Privados Internacionales | D15: 49420266 | F15: 0 | H15: 49420266
A16: Félix Estrada | D16: 49420266 | H16: 49420266
A17: FELMER ECHEVERRIA, SOFIA | F17: 0 | H17: 0
A18: CORFO | D18: 174090817 | H18: 174090817
A19: OTAROLA ALIAGA, JAIME IGNACIO | D19: 174090817 | H19: 174090817
A20: FIA | B20: 773678590 | C20: 1107730381 | D20: 859501208 | F20: 191721024 | H20: 2932631203
A21: ABARCA REYES, LUIS PATRICIO | B21: 159037123 | C21: 211136880 | H21: 370174003
A22: CACERES CELEDON, EMILIO JOSE | D22: 461067026 | H22: 461067026
A23: CARRASCO JIMENEZ JORGE | B23: 289242004 | H23: 289242004
A24: Félix Estrada | D24: 43219853 | H24: 43219853
A25: FELMER ECHEVERRIA, SOFIA | B25: 141335807 | H25: 141335807
A26: MARTINEZ CASTILLO, JUAN PABLO | C26: 188863161 | H26: 188863161
A27: OTAROLA ALIAGA, JAIME IGNACIO | B27: 184063656 | C27: 410701484 | D27: 197750395 | H27: 792515535
A28: QUEZADA JARA, MARCELO | D28: 15000000 | H28: 15000000
A29: RUBILAR TORRES, FELIPE ANDRES | C29: 77243376 | H29: 77243376
A30: SAGREDO DIAZ, BORIS | D30: 142463934 | H30: 142463934
A31: VEGA CANDIA, BARBARA CHANTAL | F31: 191721024 | H31: 191721024
A32: DONOSO CONTRERAS, JOSE MANUEL | C32: 219785480 | H32: 219785480
A33: FIC | B33: 1053487096 | D33: 1148579329 | H33: 2202066425
A34: ABARCA REYES, LUIS PATRICIO | B34: 187949539 | H34: 187949539
A35: CACERES CELEDON, EMILIO JOSE | D35: 179899000 | H35: 179899000
A36: CARRASCO JIMENEZ JORGE | D36: 233558000 | H36: 233558000
A37: FELMER ECHEVERRIA, SOFIA | B37: 242000000 | H37: 242000000
A38: LEMUS SEPULVEDA, GAMALIER FDO | B38: 239861000 | H38: 239861000
A39: OTAROLA ALIAGA, JAIME IGNACIO | D39: 554591075 | H39: 554591075
A40: SAGREDO DIAZ, BORIS | B40: 207246845 | H40: 207246845
A41: VEGA CANDIA, BARBARA CHANTAL | B41: 176429712 | D41: 180531254 | H41: 356960966
A42: FNDR Antofagasta | B42: 1128650000 | H42: 1128650000
A43: VEGA CANDIA, BARBARA CHANTAL | B43: 1128650000 | H43: 1128650000
...

Sheet Analisis perfiles may 25
A2: AÑO | B2: (Varios elementos)
A3: ID- Perfil | B3: (Todas)
A5: Cuenta de TÍTULO | B5: Etiquetas de columna
A6: Etiquetas de fila | B6: Adjudicado | C6: No Adjudicado | D6: No Postulado | E6: Postulado | F6: Total general
A7: ABARCA REYES, LUIS PATRICIO | D7: 1 | E7: 1 | F7: 2
A8: Atimira Passalacqua Fabiola | B8: 1 | F8: 1
A9: CACERES CELEDON, EMILIO JOSE | C9: 1 | F9: 1
A10: DONOSO CONTRERAS, JOSE MANUEL | C10: 2 | E10: 2 | F10: 4
A11: ESTRADA BRAVO, FELIX RODOLFO | C11: 1 | E11: 1 | F11: 2
A12: MARTINEZ CASTILLO, JUAN PABLO | C12: 1 | D12: 1 | E12: 3 | F12: 5
A13: OTAROLA ALIAGA, JAIME IGNACIO | B13: 1 | C13: 1 | E13: 1 | F13: 3
A14: QUEZADA JARA, MARCELO | B14: 1 | C14: 1 | F14: 2
A15: Riquelme Toledo Danae | B15: 1 | F15: 1
A16: RUBILAR TORRES, FELIPE ANDRES | B16: 1 | E16: 1 | F16: 2
A17: SAGREDO DIAZ, BORIS | C17: 1 | F17: 1
A18: VEGA CANDIA, BARBARA CHANTAL | C18: 1 | F18: 1
A19: Total general | B19: 5 | C19: 9 | D19: 2 | E19: 9 | F19: 25

Sheet JC PErfiles
C2: Investigador | D2: Adjudicado | E2: No Adjudicado | F2: En Concurso | G2: Total general
C3: ABARCA REYES, LUIS PATRICIO | D3: 2 | G3: =+D3+E3+F3 -> 2
C4: Atimira Passalacqua Fabiola | F4: 1 | G4: =+D4+E4+F4 -> 1
C5: CACERES CELEDON, EMILIO JOSE | E5: 3 | G5: =+D5+E5+F5 -> 3
C6: CARRASCO JIMENEZ JORGE | E6: 1 | G6: =+D6+E6+F6 -> 1
C7: DONOSO CONTRERAS, JOSE MANUEL | E7: 3 | G7: =+D7+E7+F7 -> 3
C8: ESTRADA BRAVO, FELIX RODOLFO | E8: 5 | F8: 1 | G8: =+D8+E8+F8 -> 6
C9: MARTINEZ CASTILLO, JUAN PABLO | D9: 1 | E9: 2 | F9: 1 | G9: =+D9+E9+F9 -> 4
C10: OTAROLA ALIAGA, JAIME IGNACIO | D10: 1 | E10: 1 | F10: 1 | G10: =+D10+E10+F10 -> 3
C11: QUEZADA JARA, MARCELO | E11: 1 | F11: 1 | G11: =+D11+E11+F11 -> 2
C12: Riquelme Toledo Danae | F12: 1 | G12: =+D12+E12+F12 -> 1
C13: RUBILAR TORRES, FELIPE ANDRES | F13: 1 | G13: =+D13+E13+F13 -> 1
C14: SAGREDO DIAZ, BORIS | D14: 3 | F14: 1 | G14: =+D14+E14+F14 -> 4
C15: VEGA CANDIA, BARBARA CHANTAL | D15: 1 | E15: 1 | F15: 1 | G15: =+D15+E15+F15 -> 3
C16: Total general | D16: 8 | E16: 17 | F16: 9 | G16: =SUM(G3:G15) -> 34
C35: Adjudicado | E35: En Concurso | G35: No adjudicado
B36: Fuente de Financiamiento | C36: Cant. Proyecto | D36: Monto solicitado | E36: Cant. Proyecto | F36: Monto solicitado | G36: Cant. Proyecto | H36: Monto solicitado
B37: ANID | C37: 3 | D37: 523997942 | E37: 1 | F37: 227654080 | G37: 1 | H37: 86140000
B38: Contratos Internacionales | G38: 1 | H38: 15347285
B39: CORFO | G39: 1 | H39: 103327093
B40: FIA | C40: 2 | D40: 232646890 | E40: 1 | F40: 119808000 | G40: 4 | H40: 329942915
B41: FIC | C41: 3 | D41: 498848365 | G41: 3 | H41: 520900000
B42: FONDECYT | E42: 1 | F42: 104400000 | G42: 6 | H42: 644664533
B43: FONDEF | E43: 1 | F43: 237000000
B44: FONTAGRO | G44: 1 | H44: 15347285
B45: FRPD | E45: 5 | F45: 1300452408
B46: Total general | C46: 8 | D46: 1255493197 | E46: 9 | F46: 1989314488 | G46: 17 | H46: 1715669111
C55: Etiquetas de fila | D55: Postulado | E55: Total general
C56: Concurso de Investigación Tecnológica IDeA 2025 | D56: 1 | E56: 1 | G56: Proyectos en Concurso | H56: Proyectos | I56: Monto $
C57: SAGREDO DIAZ, BORIS | D57: 1 | E57: 1 | G57: ANID | H57: 1 | I57: 227654080
C58: Convocatoria Nacional Proyectos de Innovación para el agro con Énfasis Regional 2024-2025 FIA | D58: 1 | E58: 1 | G58: MARTINEZ CASTILLO, JUAN PABLO | H58: 1 | I58: 227654080
C59: OTAROLA ALIAGA, JAIME IGNACIO | D59: 1 | E59: 1 | G59: FIA | H59: 1 | I59: 119808000
C60: Fondecyt de Iniciación en Investigación 2026 | D60: 1 | E60: 1 | G60: OTAROLA ALIAGA, JAIME IGNACIO | H60: 1 | I60: 119808000
C61: ESTRADA BRAVO, FELIX RODOLFO | D61: 1 | E61: 1 | G61: FONDECYT | H61: 1 | I61: 104400000
C62: Fondo Regional para la Productividad y el Desarrollo (FRPD)- Región de O'Higgins 2024 | D62: 5 | E62: 5 | G62: ESTRADA BRAVO, FELIX RODOLFO | H62: 1 | I62: 104400000
C63: Atimira Passalacqua Fabiola | D63: 1 | E63: 1 | G63: FONDEF | H63: 1 | I63: 237000000
C64: QUEZADA JARA, MARCELO | D64: 1 | E64: 1 | G64: SAGREDO DIAZ, BORIS | H64: 1 | I64: 237000000
C65: Riquelme Toledo Danae | D65: 1 | E65: 1 | G65: FRPD | H65: 5 | I65: 1300452408
C66: RUBILAR TORRES, FELIPE ANDRES | D66: 1 | E66: 1 | G66: ALTIMIRA PASSALACQUA, FABIOLA | H66: 1 | I66: 280000000
C67: VEGA CANDIA, BARBARA CHANTAL | D67: 1 | E67: 1 | G67: QUEZADA JARA, MARCELO | H67: 1 | I67: 280000000
...

Sheet Datos
A2: Postulado
A3: Adjudicado
A4: Rechazado
A5: No admitido

Sheet Perfiles data
C1: FECHA ACTUALIZACIÓN | D1: 45199
C2: RESPONSABLE | D2: ='Pys Post.'!F10:G10 -> #VALUE!
B3: AÑO | C3: CONCURSO O LINEA | D3: CRI | E3: TÍTULO | F3: Programas Nacionales | G3: Investigador/a Encargado/a | H3: Ejecutor Principal | I3: Estado Perfil | J3: Postulado | K3: Adjudicado | L3: Comentarios
B4: 20 de feb 16:52 | C4: Concurso de Investigación Tecnológica IDeA 2025 | D4: 16-Rayentué | E4: GENERANDO INFORMACIÓN CLAVE PARA EL DESARROLLO DE ESTRATEGIAS SUSTENTABLES DE CONTROL DEL CANCER BACTERIAL EN CEREZOS: BASADOS EN LAS CARACTERÍSTICAS DE LA POBLACIÓN DEL AGENTE CAUSAL | F4: Producción Vegetal | G4: SAGREDO DIAZ, BORIS | H4: INIA | I4: Postulado
B5: 45606 | C5: Convocatoria Nacional Proyectos de Innovación para el agro con Énfasis Regional 2024-2025 FIA | D5: 16-Rayentué | E5: Desarrollo de estrategias de riego deficitario controlado en diferentes variedades de cerezos y zonas agroclimáticas de Chile con baja disponibilidad hídrica. | F5: Programa Nacional de Agrosistemas Sustentables | G5: CACERES CELEDON, EMILIO JOSE | H5: INIA | I5: No Adjudicado
B6: 45606 | C6: Convocatoria Nacional Proyectos de Innovación para el agro con Énfasis Regional 2024-2025 FIA | D6: 16-Rayentué | E6: Empaquetamiento técnico y comercial de la primera variedad de cereza chilena para un mercado de alta exigencia en calidad | F6: Producción Vegetal | G6: OTAROLA ALIAGA, JAIME IGNACIO | H6: INIA | I6: Postulado
B7: 45581 | C7: Fondo Regional para la Productividad y el Desarrollo (FRPD)- Región de O'Higgins 2024 | D7: 16-Rayentué | E7: Desarrollo de la agricultura urbana y periurbana como alternativa de desarrollo sostenible para la producción de alimentos en la Región de O`Higgins. | F7: Programa Nacional de Agrosistemas Sustentables | G7: RUBILAR TORRES, FELIPE ANDRES | H7: INIA | I7: Postulado
B8: 45581 | C8: Fondo Regional para la Productividad y el Desarrollo (FRPD)- Región de O'Higgins 2024 | D8: 16-Rayentué | E8: OptiVol: Una plataforma digital para la optimización de la pulverización hidroneumática utilizada en frutales de hoja caduca | F8: Programa Nacional de Agrosistemas Sustentables | G8: ABARCA REYES, LUIS PATRICIO | H8: INIA | I8: No Postulado
B9: 45581 | C9: Fondo Regional para la Productividad y el Desarrollo (FRPD)- Región de O'Higgins 2024 | D9: 16-Rayentué | E9: Transferencia de un paquete tecnológico para el control de ataques de depredadores en ovinos del secano costero de O’Higgins. | F9: Programa Nacional de Producción Animal | G9: QUEZADA JARA, MARCELO | H9: INIA | I9: Postulado
B10: 45576 | C10: Fondo Regional para la Productividad y el Desarrollo (FRPD)- Región de O'Higgins 2024 | D10: 16-Rayentué | E10: Biofábricas en la región de O´Higgins, una alternativa a la producción de agroinsumos con visión agroecológica | F10: Programa Nacional de Agrosistemas Sustentables | G10: VEGA CANDIA, BARBARA CHANTAL | H10: INIA | I10: Postulado
B11: 5 de agosto de 2024 11:18 | C11: Red de Fomento Sostenible-1º Convocatoria 2024-Sector Agricultura | D11: 16-Rayentué | E11: “RedFrutiT: Red de innovación tecnológica para una fruticultura sustentable y resiliente en Chile” (Red de Fomento Sostenible-1º Convocatoria 2024-Sector Agricultura) | F11: Producción Vegetal | G11: OTAROLA ALIAGA, JAIME IGNACIO | H11: UC DAVIS CHILE - FUNDACION UC DAVIS CHILE LIFE SCIENCES INNOVATION CENTER | I11: Postulado | L11: Se ha solicitado por correo los papeles a la ejecutora principal para cerrar el proceso ya que se sabe que no fue adjudicado
B12: 31 de julio de 2024 16:57 | C12: IDeA I+D 2025 | D12: 16-Rayentué | E12: Desarrollo de un sistema de producción de plantas de tomate injertadas sobre portainjertos clonales originados por cruzamientos interespecíficos (S. lycopersicum x S. chilense) para mejorar la productividad y calidad de tomate fresco. | F12: Producción Vegetal | G12: MARTINEZ CASTILLO, JUAN PABLO | H12: INIA | I12: Postulado
B13: 4 de junio de 2024 09:25 | C13: Fondecyt Regular 2025 | D13: 16-Rayentué | E13: Improving salt tolerance of “Old Limachino Tomato” by using two clonal rootstocks issued from interspecific reciprocal crosses between wild and cultivated tomato, with different level of salt tolerance. | F13: Producción Vegetal | G13: MARTINEZ CASTILLO, JUAN PABLO | H13: INIA | I13: No Adjudicado
B14: 29 de mayo de 2024 15:11 | C14: Fondecyt Regular 2025 | D14: 16-Rayentué | E14: Disentangling the epigenetic influence on differentiation of fruit development between early and late varieties in sweet cherry (Prunus avium) (FONDECYT REGULAR) | F14: Producción Vegetal | G14: DONOSO CONTRERAS, JOSE MANUEL | H14: INIA | I14: No Adjudicado
B15: 25 de mayo de 2024 20:35 | C15: Fondecyt Regular 2025 | D15: 16-Rayentué | E15: Understanding the genetics related to orange peel disorder in sweet cherry (Prunus avium L.) | F15: Producción Vegetal | G15: DONOSO CONTRERAS, JOSE MANUEL | H15: INIA | I15: No Adjudicado
B16: 17 de abril de 2024 09:01 | C16: Convocatoria Nacional Proyectos de Innovación-Interés Privado o Bienes Públicos- para el Agro 2024 (Propuesta completa) | D16: 16-Rayentué | E16: Desarrollo de un paquete agronómico para una línea avanzada de cerezo adaptada al cambio climático: la primera variedad de la especie creada 100% en Chile | F16: Producción Vegetal | G16: DONOSO CONTRERAS, JOSE MANUEL | H16: INIA | I16: No Seleccionado
B17: 15 de abril de 2024 10:53 | C17: Fondecyt de Iniciación en Investigación 2025 | D17: 16-Rayentué | E17: A comprehensive analysis of the phenotypic plasticity of key traits for selecting quinoa genotypes (Chenopodium quinoa Willd.) under contrasting environments | F17: Producción Vegetal | G17: ESTRADA BRAVO, FELIX RODOLFO | H17: INIA | I17: No Adjudicado
B18: 45366 | C18: Instrumentos Complementarios FIA: Giras Nacionales para la Innovación 2024 | D18: 16-Rayentué | E18: Visita a experiencias de cooperativas exitosas en la Región de Los Lagos, con productores ovinos del secano costero de la Región de O'Higgins. | F18: Programa Nacional de Producción Animal | G18: QUEZADA JARA, MARCELO | H18: INIA | I18: No Adjudicado
B19: 45272 | C19: Crea y Valida Foco en Sostenibilidad 2023 | D19: 16-Rayentué | E19: Desarrollo de un agente antifúngico a partir de saponinas presentes en líneas avanzadas de quínoas chilenas | F19: Producción Vegetal | G19: ESTRADA BRAVO, FELIX RODOLFO | H19: TECNOLOGIA EN FENOMICA DE PLANTAS LIMITADA | I19: No Seleccionado
B20: 45231 | C20: Concurso Startup Ciencia 2024 (2º llamado 2023) | D20: 16-Rayentué | E20: Desarrollo de un sensor portátil (Optiriego) que optimiza el manejo de riego en tomates y uva vinífera | F20: Producción Vegetal | G20: Juan Pablo Martínuez | H20: YUMMY FRUIT SPA | I20: Adjudicado | J20: Si | K20: Si
B21: 45200 | C21: Convocatoria Nacional FIA 2023-2024 "Proyectos de Innovación en Sistemas Alimentarios Sostenibles" | D21: 16-Rayentué | E21: Diversificación floral con especies nativas y cultivos tradicionales con riego tecnificado, mejorando la disponibilidad de alimento en Apis melífera. | F21: Agrosistemas Sustentables | G21: Emilio Cáceres | H21: INIA | I21: No Adjudicado | J21: Si | K21: No | L21: Comunicación no pertinente 09-11-2023
B22: 45108 | C22: FIC O'Higgins 2023 | D22: 16-Rayentué | E22: Transferencia tecnológica y revalorización de vides criollas y productos derivados con tradición patrimonial campesina para la Región de O'Higgins | F22: Producción Vegetal | G22: Boris Sagredo | H22: INIA | I22: Adjudicado | J22: Si | K22: Si | L22: Comunicación de adjudicación 14-11-2023
B23: 45108 | C23: FIC O'Higgins 2023 | D23: 16-Rayentué | E23: Semillero colaborativo regional de variedades tradicionales INIA, en la comuna de San Vicente | F23: Producción Vegetal | G23: Bárbara Vega | H23: INIA | I23: No Adjudicado | J23: Si | K23: No
B24: 45108 | C24: FIC O'Higgins 2023 | D24: 16-Rayentué | E24: Desarrollo de soluciones técnicas para la recuperación de suelos y cultivos en terrenos afectados por desborde de ríos e inundaciones, en la pequeña y mediana agricultura en las comunas de Coltauco y San Vicente, Región de O’Higgins | F24: Agrosistemas Sustentables | G24: Jorge Carrasco | H24: INIA | I24: No adjudicado | J24: Si | K24: No | L24: No admitido por bases (faltó documentación)
B25: 45108 | C25: FIC O'Higgins 2023 | D25: 16-Rayentué | E25: Biofiltros domiciliarios para la utilización de aguas grises con riego tecnificado para la pequeña agricultura en las comunas de Pumanque, Navidad y Pichilemu | F25: Agrosistemas Sustentables | G25: Emiio Cáceres | H25: INIA | I25: No Adjudicado | J25: Si | K25: No | L25: No admitido por bases (faltó documentación)
B26: 45108 | C26: FONTAGRO 2023 | D26: 16-Rayentué | E26: Diversificación de productos funcionales de quinua para contribuir a la seguridad alimentaria | F26: Producción Vegetal | G26: Félix Estrada | H26: UNAL - Universidad Nacional de Colombia- Colombia | I26: No Adjudicado | J26: Si
B27: 45108 | C27: FIA | D27: 16-Rayentué | E27: Desarrollo de un potencial agente antifúngico a partir de saponinas presentes en líneas avanzadas de quínoa | F27: Producción Vegetal | G27: Félix Estrada | H27: Tecnofen | I27: No Adjudicado | J27: Si
B28: 45078 | C28: FONDECYT 2024 | D28: 16-Rayentué | E28: Disentangling the epigenetic influence on differentiation of fruit development between early and late varieties in sweet cherry (Prunus avium) | F28: Producción Vegetal | G28: José Manuel Donoso | H28: Universidad de Chile | I28: No Adjudicado | J28: Si
B29: 45047 | C29: Anillos de Investigación en Áreas Temáticas Específicas 2023 | D29: 16-Rayentué | E29: Plant Abiotic Stress tolerance for a Sustainable Agriculture (PASSA): Molecular Strategies for improving Plant Tolerance to drought and salinity | F29: Producción Vegetal | G29: Juan Pablo Martínez | H29: Universidad de Chile | I29: No Adjudicado | J29: Si | K29: No
